<!-- Developed by Erdi Sayar -->
<!-- It includes unncessary lines and unrelated files -->
<mujoco>
	<body mocap="true" name="robot0:mocap" pos="0 0 0">
		<geom conaffinity="0" contype="0" pos="0 0 0" rgba="0 0.5 0 0.7" size="0.005 0.005 0.005" type="box"></geom>
		<geom conaffinity="0" contype="0" pos="0 0 0" rgba="0 0.5 0 0.1" size="1 0.005 0.005" type="box"></geom>
		<geom conaffinity="0" contype="0" pos="0 0 0" rgba="0 0.5 0 0.1" size="0.005 1 0.001" type="box"></geom>
		<geom conaffinity="0" contype="0" pos="0 0 0" rgba="0 0.5 0 0.1" size="0.005 0.005 1" type="box"></geom>
	</body>

	<body childclass="robot0:fetch" name="robot0:base_link" pos="0.0 0.0 0">
		<joint armature="0.0001" axis="1 0 0" damping="1e+11" name="robot0:slide0" pos="0 0 0" type="slide"></joint>
		<joint armature="0.0001" axis="0 1 0" damping="1e+11" name="robot0:slide1" pos="0 0 0" type="slide"></joint>
		<joint armature="0.0001" axis="0 0 1" damping="1e+11" name="robot0:slide2" pos="0 0 0" type="slide"></joint>
		<inertial diaginertia="1.2869 1.2236 0.9868" mass="70.1294" pos="-0.0036 0 0.0014" quat="0.7605 -0.0133 -0.0061 0.6491"></inertial>
		<geom mesh="robot0_link0" name="robot0:base_link" material="robot0:base_mat" class="collision"></geom>
		<geom mesh="link0_0_vis" quat="0 0 -0.7071068 0.7071068" rgba="0.901961 0.921569 0.929412 1" class="visual"/>
		<geom mesh="link0_1_vis" quat="0 0 -0.7071068 0.7071068" rgba="0.25 0.25 0.25 1" class="visual"/>
		<geom mesh="link0_2_vis" quat="0 0 -0.7071068 0.7071068" rgba="0.901961 0.921569 0.929412 1" class="visual"/>
		<geom mesh="link0_3_vis" quat="0 0 -0.7071068 0.7071068" rgba="0.25 0.25 0.25 1" class="visual"/>
		<geom mesh="link0_4_vis" quat="0 0 -0.7071068 0.7071068" rgba="0.901961 0.921569 0.929412 1" class="visual"/>
		<geom mesh="link0_5_vis" quat="0 0 -0.7071068 0.7071068" rgba="0.25 0.25 0.25 1" class="visual"/>
		<geom mesh="link0_7_vis" quat="0 0 -0.7071068 0.7071068" rgba="1 1 1 1" class="visual"/>
		<geom mesh="link0_8_vis" quat="0 0 -0.7071068 0.7071068" rgba="1 1 1 1" class="visual"/>
		<geom mesh="link0_9_vis" quat="0 0 -0.7071068 0.7071068" rgba="0.25 0.25 0.25 1" class="visual"/>
		<geom mesh="link0_10_vis" quat="0 0 -0.7071068 0.7071068" rgba="0.901961 0.921569 0.929412 1" class="visual"/>
		<geom mesh="link0_11_vis" quat="0 0 -0.7071068 0.7071068" rgba="1 1 1 1" class="visual"/>
		<body name="robot0:torso_lift_link" pos="0 0 0.33">
			<inertial diaginertia="0.3365 0.3354 0.0943" mass="10.7796" pos="-0.0013 -0.0009 0.2935" quat="0.9993 -0.0006 0.0336 0.0185"></inertial>
			<joint axis="0 0 1" damping="1e+07" name="robot0:torso_lift_joint" range="-2.8973 2.8973"></joint>
			<geom mesh="robot0_link1" class="collision" name="robot0:torso_lift_link" material="robot0:torso_mat"></geom>
			<!-- <geom mesh="robot0_link1_vis" class="visual" name="robot0:torso_lift_link_vis"></geom> -->
			<geom rgba="1 1 1 1" quat="0.7071068 -0.7071068 0 0" mesh="link1_vis" class="visual"/>
			<body name="robot0:head_pan_link" pos="0 0 0" quat="0.707107 -0.707107 0 0">
				<inertial diaginertia="0.0185 0.0128 0.0095" mass="2.2556" pos="0.0321 0.0161 0.039" quat="0.5148 0.5451 -0.453 0.4823"></inertial>
				<joint pos="0 0 0" axis="0 0 1" name="robot0:head_pan_joint" range="-1.7628 1.7628"></joint>
				<geom mesh="robot0_link2" class="collision" name="robot0:head_pan_link" material="robot0:head_mat"></geom>
				<!-- <geom mesh="robot0_link2_vis" class="visual" name="robot0:head_pan_link_vis"></geom> -->
				<geom rgba="1 1 1 1" quat="0.7071068 -0.7071068 0 0" mesh="link2_vis" class="visual"/>
				<body name="robot0:shoulder_pan_link" pos="0 -0.316 0" quat="0.707107 0.707107 0 0">
					<inertial diaginertia="0.009 0.0086 0.0041" mass="2.5587" pos="0.0927 -0.0056 0.0564" quat="-0.1364 0.7624 -0.1562 0.613"></inertial>
					<joint pos="0 0 0" axis="0 0 1" name="robot0:shoulder_pan_joint" range="-3.0718 -0.0698"></joint>
					<geom mesh="robot0_link3" class="collision" name="robot0:shoulder_pan_link" material="robot0:arm_mat"></geom>
					<!-- <geom mesh="robot0_link3_vis" class="visual" name="robot0:shoulder_pan_link_vis" material="robot0:arm_mat"></geom> -->
					<geom mesh="link3_0_vis" quat="0.7071068 -0.7071068 0 0" rgba="1 1 1 1" class="visual"/>
					<geom mesh="link3_1_vis" quat="0.7071068 -0.7071068 0 0" rgba="1 1 1 1" class="visual"/>
					<geom mesh="link3_2_vis" quat="0.7071068 -0.7071068 0 0" rgba="1 1 1 1" class="visual"/>
					<geom mesh="link3_3_vis" quat="0.7071068 -0.7071068 0 0" rgba="0.25 0.25 0.25 1" class="visual"/>

					<body name="robot0:shoulder_lift_link" pos="0.0825 0 0" quat="0.707107 0.707107 0 0">
						<inertial diaginertia="0.0116 0.0112 0.0023" mass="2.6615" pos="0.1432 0.0072 -0.0001" quat="0.4382 0.4382 0.555 0.555"></inertial>
						<joint pos="0 0 0" axis="0 0 1" name="robot0:shoulder_lift_joint" range="-1.221 1.518"></joint>
						<geom mesh="robot0_link4" class="collision" name="robot0:shoulder_lift_link" material="robot0:arm_mat"></geom>
						<!-- <geom mesh="robot0_link4_vis" class="visual" name="robot0:shoulder_lift_link_vis"></geom> -->
						<geom mesh="link4_0_vis" quat="0.7071068 -0.7071068 0 0" rgba="1 1 1 1" class="visual"/>
						<geom mesh="link4_1_vis" quat="0.7071068 -0.7071068 0 0" rgba="1 1 1 1" class="visual"/>
						<geom mesh="link4_2_vis" quat="0.7071068 -0.7071068 0 0" rgba="0.25 0.25 0.25 1" class="visual"/>
						<geom mesh="link4_3_vis" quat="0.7071068 -0.7071068 0 0" rgba="1 1 1 1" class="visual"/>
						<body name="robot0:upperarm_roll_link" pos="-0.0825 0.384 0" quat="0.707107 -0.707107 0 0">
							<inertial diaginertia="0.0047 0.0045 0.0019" mass="2.3311" pos="0.1165 0.0014 0" quat="-0.0136 0.707 0.0136 0.707"></inertial>
							<joint pos="0 0 0" axis="0 0 1" limited="true" range="-2.8973 2.8973" name="robot0:upperarm_roll_joint"></joint>
							<geom mesh="robot0_link5" class="collision" name="robot0:upperarm_roll_link"></geom>
							<!-- <geom mesh="robot0_link5_vis" class="visual" name="robot0:upperarm_roll_link_vis"></geom> -->
							<geom mesh="link5_0_vis" quat="0.7071068 -0.7071068 0 0" rgba="0.25 0.25 0.25 1" class="visual"/>
							<geom mesh="link5_1_vis" quat="0.7071068 -0.7071068 0 0" rgba="1 1 1 1" class="visual"/>
							<geom mesh="link5_2_vis" quat="0.7071068 -0.7071068 0 0" rgba="1 1 1 1" class="visual"/>
							<body name="robot0:elbow_flex_link" pos="0 0 0" quat="0.707107 0.707107 0 0">
								<inertial diaginertia="0.0086 0.0084 0.002" mass="2.1299" pos="0.1279 0.0073 0" quat="0.4332 0.4332 0.5589 0.5589"></inertial>
								<joint pos="0 0 0" axis="0 0 1" limited="true" range="-0.0175 3.7525" name="robot0:elbow_flex_joint"></joint>
								<geom mesh="robot0_link6" class="collision" name="robot0:elbow_flex_link"></geom>
								<!-- <geom mesh="robot0_link6_vis" class="visual" name="robot0:elbow_flex_link_vis"></geom> -->
								<geom mesh="link6_0_vis" quat="0.7071068 -0.7071068 0 0" rgba="0.901961 0.921569 0.929412 1" class="visual"/>
								<geom mesh="link6_1_vis" quat="0.7071068 -0.7071068 0 0" rgba="1 1 1 1" class="visual"/>
								<geom mesh="link6_2_vis" quat="0.7071068 -0.7071068 0 0" rgba="0.25 0.25 0.25 1" class="visual"/>
								<geom mesh="link6_3_vis" quat="0.7071068 -0.7071068 0 0" rgba="1 1 1 1" class="visual"/>
								<geom mesh="link6_4_vis" quat="0.7071068 -0.7071068 0 0" rgba="1 1 1 1" class="visual"/>
								<geom mesh="link6_5_vis" quat="0.7071068 -0.7071068 0 0" rgba="1 1 1 1" class="visual"/>
								<geom mesh="link6_6_vis" quat="0.7071068 -0.7071068 0 0" rgba="1 1 1 1" class="visual"/>
								<geom mesh="link6_8_vis" quat="0.7071068 -0.7071068 0 0" rgba="0.039216 0.541176 0.780392 1" class="visual"/>
								<geom mesh="link6_9_vis" quat="0.7071068 -0.7071068 0 0" rgba="0.25 0.25 0.25 1" class="visual"/>
								<geom mesh="link6_10_vis" quat="0.7071068 -0.7071068 0 0" rgba="0.25 0.25 0.25 1" class="visual"/>
								<geom mesh="link6_11_vis" quat="0.7071068 -0.7071068 0 0" rgba="1 1 1 1" class="visual"/>
								<geom mesh="link6_13_vis" quat="0.7071068 -0.7071068 0 0" rgba="1 1 1 1" class="visual"/>
								<geom mesh="link6_14_vis" quat="0.7071068 -0.7071068 0 0" rgba="0.25 0.25 0.25 1" class="visual"/>
								<geom mesh="link6_15_vis" quat="0.7071068 -0.7071068 0 0" rgba="0.25 0.25 0.25 1" class="visual"/>
								<geom mesh="link6_16_vis" quat="0.7071068 -0.7071068 0 0" rgba="1 1 1 1" class="visual"/>
								<body name="robot0:forearm_roll_link" pos="0.088 0 0" quat="0.707107 0.707107 0 0">
									<inertial diaginertia="0.0035 0.0031 0.0015" mass="1.6563" pos="0.1097 -0.0266 0" quat="-0.0715 0.7035 0.0715 0.7035"></inertial>
									<joint pos="0 0 0" axis="0 0 1" limited="true" range="-2.8973 2.8973" armature="2.7538" damping="3.5247" frictionloss="0" name="robot0:forearm_roll_joint" stiffness="10"></joint>
									<geom mesh="robot0_link7" class="collision" name="robot0:forearm_roll_link"></geom>
									<!-- <geom mesh="robot0_link7_vis" class="visual" name="robot0:forearm_roll_link_vis"></geom> -->
									<geom mesh="link7_0_vis" quat="0.7071068 -0.7071068 0 0" rgba="1 1 1 1" class="visual"/>
									<geom mesh="link7_1_vis" quat="0.7071068 -0.7071068 0 0" rgba="0.25 0.25 0.25 1" class="visual"/>
									<geom mesh="link7_2_vis" quat="0.7071068 -0.7071068 0 0" rgba="0.25 0.25 0.25 1" class="visual"/>
									<geom mesh="link7_3_vis" quat="0.7071068 -0.7071068 0 0" rgba="0.25 0.25 0.25 1" class="visual"/>
									<geom mesh="link7_4_vis" quat="0.7071068 -0.7071068 0 0" rgba="0.25 0.25 0.25 1" class="visual"/>
									<geom mesh="link7_5_vis" quat="0.7071068 -0.7071068 0 0" rgba="0.25 0.25 0.25 1" class="visual"/>
									<geom mesh="link7_6_vis" quat="0.7071068 -0.7071068 0 0" rgba="0.25 0.25 0.25 1" class="visual"/>
									<geom mesh="link7_7_vis" quat="0.7071068 -0.7071068 0 0" rgba="0.25 0.25 0.25 1" class="visual"/>
									<body name="robot0_right_hand" pos="0 0 0.1065" quat="0.923785 0 0 -0.382911">
										<inertial pos="0 0 0" mass="0.5" diaginertia="0.05 0.05 0.05" />
										<camera name="robot0_eye_in_hand" pos="0.05 0 0" quat="0 0.707108 0.707108 0" fovy="75" />
										<body name="gripper0_right_gripper" pos="0 0 0" quat="0.707107 0 0 -0.707107">
											<inertial pos="0 0 0.17" quat="0.707107 0.707107 0 0" mass="0.3" diaginertia="0.09 0.07 0.05" />
											<geom name="gripper0_hand_visual" quat="0.707107 0 0 0.707107" class="visual" mesh="gripper0_hand_vis" />
											<geom name="gripper0_hand_collision" quat="0.707107 0 0 0.707107" class="collision" mesh="gripper0_hand" />
											<site name="gripper0_ft_frame" pos="0 0 0" size="0.01" group="1" rgba="1 0 0 1" />
											<body name="robot0:gripper_link" pos="0 0 0.097">
												<inertial pos="0 0 0.097" mass="0" diaginertia="0 0 0" />
												<site name="robot0:grip" pos="0 0.0 0" size="0.01" group="1" rgba="1 0 0 0.0" />
												<site name="gripper0_ee_x" pos="0.1 0 0" quat="0.707105 0 0.707108 0" size="0.005 0.1" group="1" type="cylinder" rgba="1 0 0 0" />
												<site name="gripper0_ee_y" pos="0 0.1 0" quat="0.707105 0.707108 0 0" size="0.005 0.1" group="1" type="cylinder" rgba="0 1 0 0" />
												<site name="gripper0_ee_z" pos="0 0 0.1" size="0.005 0.1" group="1" type="cylinder" rgba="0 0 1 0" />
												<site name="robot0:grip_cylinder" pos="0 0 0" size="0.005 10" group="1" type="cylinder" rgba="0 1 0 0.3" />
											</body>
											<body name="gripper0_leftfinger" pos="0 0 0.0524" quat="0.707107 0 0 0.707107">
												<inertial diaginertia="0.1 0.1 0.1" mass="4" pos="-0.01 0 0"></inertial>
												<joint name="robot0_finger_joint1" pos="0 0 0" axis="0 1 0" type="slide" limited="true" range="-0.01 0.05" damping="100" armature="1.0" frictionloss="1.0"/>

												<site type="box" pos="0 0.008 0.0385" size="0.0185 0.010 0.0385" quat="0 0 0 1" rgba="1.0 0.0 0.0 1.0" name="force_sensor_l"></site>
												<geom pos="0 0.008 0.0385" size="0.0185 0.007 0.0385" type="box" rgba="0.901961 0.921569 0.929412 1" name="robot0:r_gripper_finger_link"></geom>

											</body>
											<body name="gripper0_rightfinger" pos="0 0 0.0524" quat="0.707107 0 0 0.707107">
												<inertial diaginertia="0.1 0.1 0.1" mass="4" pos="-0.01 0 0"></inertial>
												<joint name="robot0_finger_joint2" pos="0 0 0" axis="0 -1 0" type="slide" limited="true" range="-0.01 0.05" damping="100" armature="1.0" frictionloss="1.0"/>
												<geom pos="0 -0.008 0.0385" size="0.0185 0.007 0.0385" type="box" rgba="0.901961 0.921569 0.929412 1" name="robot0:l_gripper_finger_link"></geom>
												<site type="box" pos="0 -0.008 0.0385" size="0.0185 0.010 0.0385" euler="0 0 0" rgba="1.0 1.0 0.0 1.0" name="force_sensor_r"></site>
											</body>
										</body>
									</body>
								</body>
							</body>
						</body>
					</body>
				</body>
			</body>
		</body>

		<body name="robot0:external_camera_body_0" pos="0 0 0">
			<camera euler="0 0.75 1.57" fovy="43.3" name="external_camera_0" pos="1.3 0 1.2"></camera>
		</body>
	</body>
</mujoco>
